[2023-11-06T10:37:17.184+0530] {taskinstance.py:1157} INFO - Dependencies all met for dep_context=non-requeueable deps ti=<TaskInstance: hooks_demo.transfer manual__2023-11-06T05:07:14.887627+00:00 [queued]>
[2023-11-06T10:37:17.188+0530] {taskinstance.py:1157} INFO - Dependencies all met for dep_context=requeueable deps ti=<TaskInstance: hooks_demo.transfer manual__2023-11-06T05:07:14.887627+00:00 [queued]>
[2023-11-06T10:37:17.188+0530] {taskinstance.py:1359} INFO - Starting attempt 1 of 2
[2023-11-06T10:37:17.201+0530] {taskinstance.py:1380} INFO - Executing <Task(PythonOperator): transfer> on 2023-11-06 05:07:14.887627+00:00
[2023-11-06T10:37:17.204+0530] {standard_task_runner.py:57} INFO - Started process 9860 to run task
[2023-11-06T10:37:17.206+0530] {standard_task_runner.py:84} INFO - Running: ['airflow', 'tasks', 'run', 'hooks_demo', 'transfer', 'manual__2023-11-06T05:07:14.887627+00:00', '--job-id', '4269', '--raw', '--subdir', 'DAGS_FOLDER/hooks.py', '--cfg-path', '/tmp/tmphg21d9w1']
[2023-11-06T10:37:17.207+0530] {standard_task_runner.py:85} INFO - Job 4269: Subtask transfer
[2023-11-06T10:37:17.233+0530] {task_command.py:415} INFO - Running <TaskInstance: hooks_demo.transfer manual__2023-11-06T05:07:14.887627+00:00 [running]> on host harika-Latitude-5511
[2023-11-06T10:37:17.373+0530] {taskinstance.py:1660} INFO - Exporting env vars: AIRFLOW_CTX_DAG_OWNER='Airflow' AIRFLOW_CTX_DAG_ID='hooks_demo' AIRFLOW_CTX_TASK_ID='transfer' AIRFLOW_CTX_EXECUTION_DATE='2023-11-06T05:07:14.887627+00:00' AIRFLOW_CTX_TRY_NUMBER='1' AIRFLOW_CTX_DAG_RUN_ID='manual__2023-11-06T05:07:14.887627+00:00'
[2023-11-06T10:37:17.377+0530] {base.py:73} INFO - Using connection ID 'postgres_conn' for task execution.
[2023-11-06T10:37:17.392+0530] {base.py:73} INFO - Using connection ID 'postgres_conn' for task execution.
[2023-11-06T10:37:17.402+0530] {taskinstance.py:1935} ERROR - Task failed with exception
Traceback (most recent call last):
  File "/home/harika/.local/lib/python3.10/site-packages/airflow/operators/python.py", line 192, in execute
    return_value = self.execute_callable()
  File "/home/harika/.local/lib/python3.10/site-packages/airflow/operators/python.py", line 209, in execute_callable
    return self.python_callable(*self.op_args, **self.op_kwargs)
  File "/home/harika/airflow/dags/hooks.py", line 28, in transfer_function
    source_cursor.execute(query)
psycopg2.errors.UndefinedTable: relation "source_city_table" does not exist
LINE 1: select * from source_city_table
                      ^

[2023-11-06T10:37:17.405+0530] {taskinstance.py:1398} INFO - Marking task as UP_FOR_RETRY. dag_id=hooks_demo, task_id=transfer, execution_date=20231106T050714, start_date=20231106T050717, end_date=20231106T050717
[2023-11-06T10:37:17.412+0530] {standard_task_runner.py:104} ERROR - Failed to execute job 4269 for task transfer (relation "source_city_table" does not exist
LINE 1: select * from source_city_table
                      ^
; 9860)
[2023-11-06T10:37:17.458+0530] {local_task_job_runner.py:228} INFO - Task exited with return code 1
[2023-11-06T10:37:17.487+0530] {taskinstance.py:2776} INFO - 0 downstream tasks scheduled from follow-on schedule check
