[2023-11-03T14:05:04.103+0530] {taskinstance.py:1157} INFO - Dependencies all met for dep_context=non-requeueable deps ti=<TaskInstance: hooks_demo.transfer manual__2023-11-03T08:29:59.861548+00:00 [queued]>
[2023-11-03T14:05:04.109+0530] {taskinstance.py:1157} INFO - Dependencies all met for dep_context=requeueable deps ti=<TaskInstance: hooks_demo.transfer manual__2023-11-03T08:29:59.861548+00:00 [queued]>
[2023-11-03T14:05:04.109+0530] {taskinstance.py:1359} INFO - Starting attempt 2 of 2
[2023-11-03T14:05:04.119+0530] {taskinstance.py:1380} INFO - Executing <Task(PythonOperator): transfer> on 2023-11-03 08:29:59.861548+00:00
[2023-11-03T14:05:04.122+0530] {standard_task_runner.py:57} INFO - Started process 1312425 to run task
[2023-11-03T14:05:04.124+0530] {standard_task_runner.py:84} INFO - Running: ['airflow', 'tasks', 'run', 'hooks_demo', 'transfer', 'manual__2023-11-03T08:29:59.861548+00:00', '--job-id', '4195', '--raw', '--subdir', 'DAGS_FOLDER/hooks.py', '--cfg-path', '/tmp/tmp5vhzd5r2']
[2023-11-03T14:05:04.124+0530] {standard_task_runner.py:85} INFO - Job 4195: Subtask transfer
[2023-11-03T14:05:04.145+0530] {task_command.py:415} INFO - Running <TaskInstance: hooks_demo.transfer manual__2023-11-03T08:29:59.861548+00:00 [running]> on host harika-Latitude-5511
[2023-11-03T14:05:04.252+0530] {taskinstance.py:1660} INFO - Exporting env vars: AIRFLOW_CTX_DAG_OWNER='Airflow' AIRFLOW_CTX_DAG_ID='hooks_demo' AIRFLOW_CTX_TASK_ID='transfer' AIRFLOW_CTX_EXECUTION_DATE='2023-11-03T08:29:59.861548+00:00' AIRFLOW_CTX_TRY_NUMBER='2' AIRFLOW_CTX_DAG_RUN_ID='manual__2023-11-03T08:29:59.861548+00:00'
[2023-11-03T14:05:04.256+0530] {base.py:73} INFO - Using connection ID 'postgres_conn' for task execution.
[2023-11-03T14:05:04.257+0530] {taskinstance.py:1935} ERROR - Task failed with exception
Traceback (most recent call last):
  File "/home/harika/.local/lib/python3.10/site-packages/airflow/operators/python.py", line 192, in execute
    return_value = self.execute_callable()
  File "/home/harika/.local/lib/python3.10/site-packages/airflow/operators/python.py", line 209, in execute_callable
    return self.python_callable(*self.op_args, **self.op_kwargs)
  File "/home/harika/airflow/dags/hooks.py", line 20, in transfer_function
    source_conn = source_hook.get_conn()
  File "/home/harika/.local/lib/python3.10/site-packages/airflow/providers/postgres/hooks/postgres.py", line 155, in get_conn
    self.conn = psycopg2.connect(**conn_args)
  File "/home/harika/.local/lib/python3.10/site-packages/psycopg2/__init__.py", line 122, in connect
    conn = _connect(dsn, connection_factory=connection_factory, **kwasync)
psycopg2.OperationalError: could not translate host name "local" to address: Temporary failure in name resolution

[2023-11-03T14:05:04.260+0530] {taskinstance.py:1398} INFO - Marking task as FAILED. dag_id=hooks_demo, task_id=transfer, execution_date=20231103T082959, start_date=20231103T083504, end_date=20231103T083504
[2023-11-03T14:05:04.272+0530] {standard_task_runner.py:104} ERROR - Failed to execute job 4195 for task transfer (could not translate host name "local" to address: Temporary failure in name resolution
; 1312425)
[2023-11-03T14:05:04.295+0530] {local_task_job_runner.py:228} INFO - Task exited with return code 1
[2023-11-03T14:05:04.303+0530] {taskinstance.py:2776} INFO - 0 downstream tasks scheduled from follow-on schedule check
