[2023-11-16T16:01:40.287+0530] {taskinstance.py:1157} INFO - Dependencies all met for dep_context=non-requeueable deps ti=<TaskInstance: hooks_demo.transfer manual__2023-11-16T10:31:35.835686+00:00 [queued]>
[2023-11-16T16:01:40.291+0530] {taskinstance.py:1157} INFO - Dependencies all met for dep_context=requeueable deps ti=<TaskInstance: hooks_demo.transfer manual__2023-11-16T10:31:35.835686+00:00 [queued]>
[2023-11-16T16:01:40.291+0530] {taskinstance.py:1359} INFO - Starting attempt 1 of 2
[2023-11-16T16:01:40.301+0530] {taskinstance.py:1380} INFO - Executing <Task(PythonOperator): transfer> on 2023-11-16 10:31:35.835686+00:00
[2023-11-16T16:01:40.304+0530] {standard_task_runner.py:57} INFO - Started process 146050 to run task
[2023-11-16T16:01:40.306+0530] {standard_task_runner.py:84} INFO - Running: ['airflow', 'tasks', 'run', 'hooks_demo', 'transfer', 'manual__2023-11-16T10:31:35.835686+00:00', '--job-id', '4734', '--raw', '--subdir', 'DAGS_FOLDER/hooks.py', '--cfg-path', '/tmp/tmp9wdstg73']
[2023-11-16T16:01:40.307+0530] {standard_task_runner.py:85} INFO - Job 4734: Subtask transfer
[2023-11-16T16:01:40.329+0530] {task_command.py:415} INFO - Running <TaskInstance: hooks_demo.transfer manual__2023-11-16T10:31:35.835686+00:00 [running]> on host harika-Latitude-5511
[2023-11-16T16:01:40.467+0530] {taskinstance.py:1660} INFO - Exporting env vars: AIRFLOW_CTX_DAG_OWNER='Airflow' AIRFLOW_CTX_DAG_ID='hooks_demo' AIRFLOW_CTX_TASK_ID='transfer' AIRFLOW_CTX_EXECUTION_DATE='2023-11-16T10:31:35.835686+00:00' AIRFLOW_CTX_TRY_NUMBER='1' AIRFLOW_CTX_DAG_RUN_ID='manual__2023-11-16T10:31:35.835686+00:00'
[2023-11-16T16:01:40.472+0530] {base.py:73} INFO - Using connection ID 'postgres_conn' for task execution.
[2023-11-16T16:01:40.484+0530] {base.py:73} INFO - Using connection ID 'postgres_conn' for task execution.
[2023-11-16T16:01:40.494+0530] {taskinstance.py:1935} ERROR - Task failed with exception
Traceback (most recent call last):
  File "/home/harika/.local/lib/python3.10/site-packages/airflow/operators/python.py", line 192, in execute
    return_value = self.execute_callable()
  File "/home/harika/.local/lib/python3.10/site-packages/airflow/operators/python.py", line 209, in execute_callable
    return self.python_callable(*self.op_args, **self.op_kwargs)
  File "/home/harika/airflow/dags/hooks.py", line 36, in transfer_function
    source_cursor.execute(qqq)
psycopg2.errors.InvalidSchemaName: schema "airflow" does not exist

[2023-11-16T16:01:40.497+0530] {taskinstance.py:1398} INFO - Marking task as UP_FOR_RETRY. dag_id=hooks_demo, task_id=transfer, execution_date=20231116T103135, start_date=20231116T103140, end_date=20231116T103140
[2023-11-16T16:01:40.504+0530] {standard_task_runner.py:104} ERROR - Failed to execute job 4734 for task transfer (schema "airflow" does not exist
; 146050)
[2023-11-16T16:01:40.518+0530] {local_task_job_runner.py:228} INFO - Task exited with return code 1
[2023-11-16T16:01:40.531+0530] {taskinstance.py:2776} INFO - 0 downstream tasks scheduled from follow-on schedule check
