[2023-11-16T12:43:48.380+0530] {taskinstance.py:1157} INFO - Dependencies all met for dep_context=non-requeueable deps ti=<TaskInstance: hooks_demo.tables manual__2023-11-16T07:13:45.012609+00:00 [queued]>
[2023-11-16T12:43:48.384+0530] {taskinstance.py:1157} INFO - Dependencies all met for dep_context=requeueable deps ti=<TaskInstance: hooks_demo.tables manual__2023-11-16T07:13:45.012609+00:00 [queued]>
[2023-11-16T12:43:48.384+0530] {taskinstance.py:1359} INFO - Starting attempt 1 of 2
[2023-11-16T12:43:48.393+0530] {taskinstance.py:1380} INFO - Executing <Task(PythonOperator): tables> on 2023-11-16 07:13:45.012609+00:00
[2023-11-16T12:43:48.396+0530] {standard_task_runner.py:57} INFO - Started process 122765 to run task
[2023-11-16T12:43:48.398+0530] {standard_task_runner.py:84} INFO - Running: ['airflow', 'tasks', 'run', 'hooks_demo', 'tables', 'manual__2023-11-16T07:13:45.012609+00:00', '--job-id', '4682', '--raw', '--subdir', 'DAGS_FOLDER/hooks.py', '--cfg-path', '/tmp/tmpbf_vgg7o']
[2023-11-16T12:43:48.399+0530] {standard_task_runner.py:85} INFO - Job 4682: Subtask tables
[2023-11-16T12:43:48.423+0530] {task_command.py:415} INFO - Running <TaskInstance: hooks_demo.tables manual__2023-11-16T07:13:45.012609+00:00 [running]> on host harika-Latitude-5511
[2023-11-16T12:43:48.560+0530] {taskinstance.py:1660} INFO - Exporting env vars: AIRFLOW_CTX_DAG_OWNER='Airflow' AIRFLOW_CTX_DAG_ID='hooks_demo' AIRFLOW_CTX_TASK_ID='tables' AIRFLOW_CTX_EXECUTION_DATE='2023-11-16T07:13:45.012609+00:00' AIRFLOW_CTX_TRY_NUMBER='1' AIRFLOW_CTX_DAG_RUN_ID='manual__2023-11-16T07:13:45.012609+00:00'
[2023-11-16T12:43:48.565+0530] {base.py:73} INFO - Using connection ID 'postgres_conn' for task execution.
[2023-11-16T12:43:48.576+0530] {logging_mixin.py:151} INFO - query executed
[2023-11-16T12:43:48.576+0530] {taskinstance.py:1935} ERROR - Task failed with exception
Traceback (most recent call last):
  File "/home/harika/.local/lib/python3.10/site-packages/airflow/operators/python.py", line 192, in execute
    return_value = self.execute_callable()
  File "/home/harika/.local/lib/python3.10/site-packages/airflow/operators/python.py", line 209, in execute_callable
    return self.python_callable(*self.op_args, **self.op_kwargs)
  File "/home/harika/airflow/dags/hooks.py", line 63, in list_tables
    table_names = [row[0] for row in cursor.fetchall()]
psycopg2.ProgrammingError: no results to fetch
[2023-11-16T12:43:48.579+0530] {taskinstance.py:1398} INFO - Marking task as UP_FOR_RETRY. dag_id=hooks_demo, task_id=tables, execution_date=20231116T071345, start_date=20231116T071348, end_date=20231116T071348
[2023-11-16T12:43:48.585+0530] {standard_task_runner.py:104} ERROR - Failed to execute job 4682 for task tables (no results to fetch; 122765)
[2023-11-16T12:43:48.610+0530] {local_task_job_runner.py:228} INFO - Task exited with return code 1
[2023-11-16T12:43:48.620+0530] {taskinstance.py:2776} INFO - 0 downstream tasks scheduled from follow-on schedule check
