[2023-11-16T15:44:33.236+0530] {taskinstance.py:1157} INFO - Dependencies all met for dep_context=non-requeueable deps ti=<TaskInstance: hooks_demo.transfer manual__2023-11-16T10:14:28.370478+00:00 [queued]>
[2023-11-16T15:44:33.240+0530] {taskinstance.py:1157} INFO - Dependencies all met for dep_context=requeueable deps ti=<TaskInstance: hooks_demo.transfer manual__2023-11-16T10:14:28.370478+00:00 [queued]>
[2023-11-16T15:44:33.240+0530] {taskinstance.py:1359} INFO - Starting attempt 1 of 2
[2023-11-16T15:44:33.250+0530] {taskinstance.py:1380} INFO - Executing <Task(PythonOperator): transfer> on 2023-11-16 10:14:28.370478+00:00
[2023-11-16T15:44:33.253+0530] {standard_task_runner.py:57} INFO - Started process 144338 to run task
[2023-11-16T15:44:33.255+0530] {standard_task_runner.py:84} INFO - Running: ['airflow', 'tasks', 'run', 'hooks_demo', 'transfer', 'manual__2023-11-16T10:14:28.370478+00:00', '--job-id', '4724', '--raw', '--subdir', 'DAGS_FOLDER/hooks.py', '--cfg-path', '/tmp/tmpr9rfsapo']
[2023-11-16T15:44:33.256+0530] {standard_task_runner.py:85} INFO - Job 4724: Subtask transfer
[2023-11-16T15:44:33.278+0530] {task_command.py:415} INFO - Running <TaskInstance: hooks_demo.transfer manual__2023-11-16T10:14:28.370478+00:00 [running]> on host harika-Latitude-5511
[2023-11-16T15:44:33.415+0530] {taskinstance.py:1660} INFO - Exporting env vars: AIRFLOW_CTX_DAG_OWNER='Airflow' AIRFLOW_CTX_DAG_ID='hooks_demo' AIRFLOW_CTX_TASK_ID='transfer' AIRFLOW_CTX_EXECUTION_DATE='2023-11-16T10:14:28.370478+00:00' AIRFLOW_CTX_TRY_NUMBER='1' AIRFLOW_CTX_DAG_RUN_ID='manual__2023-11-16T10:14:28.370478+00:00'
[2023-11-16T15:44:33.419+0530] {base.py:73} INFO - Using connection ID 'postgres_conn' for task execution.
[2023-11-16T15:44:33.431+0530] {base.py:73} INFO - Using connection ID 'postgres_conn' for task execution.
[2023-11-16T15:44:33.440+0530] {taskinstance.py:1935} ERROR - Task failed with exception
Traceback (most recent call last):
  File "/home/harika/.local/lib/python3.10/site-packages/airflow/operators/python.py", line 192, in execute
    return_value = self.execute_callable()
  File "/home/harika/.local/lib/python3.10/site-packages/airflow/operators/python.py", line 209, in execute_callable
    return self.python_callable(*self.op_args, **self.op_kwargs)
  File "/home/harika/airflow/dags/hooks.py", line 36, in transfer_function
    source_cursor.execute(insert_query)
psycopg2.errors.UndefinedTable: relation "airflow.***" does not exist
LINE 1: insert into airflow.***(city_name, city_code) values('Hydera...
                    ^

[2023-11-16T15:44:33.443+0530] {taskinstance.py:1398} INFO - Marking task as UP_FOR_RETRY. dag_id=hooks_demo, task_id=transfer, execution_date=20231116T101428, start_date=20231116T101433, end_date=20231116T101433
[2023-11-16T15:44:33.450+0530] {standard_task_runner.py:104} ERROR - Failed to execute job 4724 for task transfer (relation "airflow.***" does not exist
LINE 1: insert into airflow.***(city_name, city_code) values('Hydera...
                    ^
; 144338)
[2023-11-16T15:44:33.467+0530] {local_task_job_runner.py:228} INFO - Task exited with return code 1
[2023-11-16T15:44:33.476+0530] {taskinstance.py:2776} INFO - 0 downstream tasks scheduled from follow-on schedule check
