[2023-10-17T12:42:54.818+0530] {taskinstance.py:1157} INFO - Dependencies all met for dep_context=non-requeueable deps ti=<TaskInstance: pdf_extract.extract_text_from_pdf scheduled__2023-10-16T00:00:00+00:00 [queued]>
[2023-10-17T12:42:54.823+0530] {taskinstance.py:1157} INFO - Dependencies all met for dep_context=requeueable deps ti=<TaskInstance: pdf_extract.extract_text_from_pdf scheduled__2023-10-16T00:00:00+00:00 [queued]>
[2023-10-17T12:42:54.823+0530] {taskinstance.py:1359} INFO - Starting attempt 1 of 1
[2023-10-17T12:42:54.831+0530] {taskinstance.py:1380} INFO - Executing <Task(PythonOperator): extract_text_from_pdf> on 2023-10-16 00:00:00+00:00
[2023-10-17T12:42:54.833+0530] {standard_task_runner.py:57} INFO - Started process 23721 to run task
[2023-10-17T12:42:54.835+0530] {standard_task_runner.py:84} INFO - Running: ['airflow', 'tasks', 'run', 'pdf_extract', 'extract_text_from_pdf', 'scheduled__2023-10-16T00:00:00+00:00', '--job-id', '315', '--raw', '--subdir', 'DAGS_FOLDER/pdf_extract.py', '--cfg-path', '/tmp/tmpl2t68v4d']
[2023-10-17T12:42:54.835+0530] {standard_task_runner.py:85} INFO - Job 315: Subtask extract_text_from_pdf
[2023-10-17T12:42:54.857+0530] {task_command.py:415} INFO - Running <TaskInstance: pdf_extract.extract_text_from_pdf scheduled__2023-10-16T00:00:00+00:00 [running]> on host harika-Latitude-5511
[2023-10-17T12:42:54.889+0530] {taskinstance.py:1660} INFO - Exporting env vars: AIRFLOW_CTX_DAG_OWNER='airflow' AIRFLOW_CTX_DAG_ID='pdf_extract' AIRFLOW_CTX_TASK_ID='extract_text_from_pdf' AIRFLOW_CTX_EXECUTION_DATE='2023-10-16T00:00:00+00:00' AIRFLOW_CTX_TRY_NUMBER='1' AIRFLOW_CTX_DAG_RUN_ID='scheduled__2023-10-16T00:00:00+00:00'
[2023-10-17T12:42:54.890+0530] {taskinstance.py:1935} ERROR - Task failed with exception
Traceback (most recent call last):
  File "/home/harika/.local/lib/python3.10/site-packages/airflow/operators/python.py", line 192, in execute
    return_value = self.execute_callable()
  File "/home/harika/.local/lib/python3.10/site-packages/airflow/operators/python.py", line 209, in execute_callable
    return self.python_callable(*self.op_args, **self.op_kwargs)
  File "/home/harika/airflow/dags/pdf_extract.py", line 21, in extract_text_from_pdf
    pdf_file.close()
UnboundLocalError: local variable 'pdf_file' referenced before assignment
[2023-10-17T12:42:54.892+0530] {taskinstance.py:1398} INFO - Marking task as FAILED. dag_id=pdf_extract, task_id=extract_text_from_pdf, execution_date=20231016T000000, start_date=20231017T071254, end_date=20231017T071254
[2023-10-17T12:42:54.899+0530] {standard_task_runner.py:104} ERROR - Failed to execute job 315 for task extract_text_from_pdf (local variable 'pdf_file' referenced before assignment; 23721)
[2023-10-17T12:42:54.927+0530] {local_task_job_runner.py:228} INFO - Task exited with return code 1
[2023-10-17T12:42:54.937+0530] {taskinstance.py:2776} INFO - 0 downstream tasks scheduled from follow-on schedule check
