[2023-10-17T13:32:24.085+0530] {taskinstance.py:1157} INFO - Dependencies all met for dep_context=non-requeueable deps ti=<TaskInstance: pdf_extract.extract_text_from_pdf scheduled__2023-10-16T00:00:00+00:00 [queued]>
[2023-10-17T13:32:24.090+0530] {taskinstance.py:1157} INFO - Dependencies all met for dep_context=requeueable deps ti=<TaskInstance: pdf_extract.extract_text_from_pdf scheduled__2023-10-16T00:00:00+00:00 [queued]>
[2023-10-17T13:32:24.090+0530] {taskinstance.py:1359} INFO - Starting attempt 2 of 2
[2023-10-17T13:32:24.099+0530] {taskinstance.py:1380} INFO - Executing <Task(PythonOperator): extract_text_from_pdf> on 2023-10-16 00:00:00+00:00
[2023-10-17T13:32:24.102+0530] {standard_task_runner.py:57} INFO - Started process 27583 to run task
[2023-10-17T13:32:24.104+0530] {standard_task_runner.py:84} INFO - Running: ['airflow', 'tasks', 'run', 'pdf_extract', 'extract_text_from_pdf', 'scheduled__2023-10-16T00:00:00+00:00', '--job-id', '316', '--raw', '--subdir', 'DAGS_FOLDER/pdf_extract.py', '--cfg-path', '/tmp/tmpp2juzw10']
[2023-10-17T13:32:24.104+0530] {standard_task_runner.py:85} INFO - Job 316: Subtask extract_text_from_pdf
[2023-10-17T13:32:24.127+0530] {task_command.py:415} INFO - Running <TaskInstance: pdf_extract.extract_text_from_pdf scheduled__2023-10-16T00:00:00+00:00 [running]> on host harika-Latitude-5511
[2023-10-17T13:32:24.161+0530] {taskinstance.py:1660} INFO - Exporting env vars: AIRFLOW_CTX_DAG_OWNER='airflow' AIRFLOW_CTX_DAG_ID='pdf_extract' AIRFLOW_CTX_TASK_ID='extract_text_from_pdf' AIRFLOW_CTX_EXECUTION_DATE='2023-10-16T00:00:00+00:00' AIRFLOW_CTX_TRY_NUMBER='2' AIRFLOW_CTX_DAG_RUN_ID='scheduled__2023-10-16T00:00:00+00:00'
[2023-10-17T13:32:24.161+0530] {taskinstance.py:1935} ERROR - Task failed with exception
Traceback (most recent call last):
  File "/home/harika/.local/lib/python3.10/site-packages/airflow/operators/python.py", line 192, in execute
    return_value = self.execute_callable()
  File "/home/harika/.local/lib/python3.10/site-packages/airflow/operators/python.py", line 209, in execute_callable
    return self.python_callable(*self.op_args, **self.op_kwargs)
  File "/home/harika/airflow/dags/pdf_extract.py", line 21, in extract_text_from_pdf
    pdf_file.close()
UnboundLocalError: local variable 'pdf_file' referenced before assignment
[2023-10-17T13:32:24.164+0530] {taskinstance.py:1398} INFO - Marking task as FAILED. dag_id=pdf_extract, task_id=extract_text_from_pdf, execution_date=20231016T000000, start_date=20231017T080224, end_date=20231017T080224
[2023-10-17T13:32:24.171+0530] {standard_task_runner.py:104} ERROR - Failed to execute job 316 for task extract_text_from_pdf (local variable 'pdf_file' referenced before assignment; 27583)
[2023-10-17T13:32:24.196+0530] {local_task_job_runner.py:228} INFO - Task exited with return code 1
[2023-10-17T13:32:24.214+0530] {taskinstance.py:2776} INFO - 0 downstream tasks scheduled from follow-on schedule check
