[2023-11-03T13:34:18.733+0530] {taskinstance.py:1157} INFO - Dependencies all met for dep_context=non-requeueable deps ti=<TaskInstance: hooks_demo.transfer manual__2023-11-03T07:59:14.612650+00:00 [queued]>
[2023-11-03T13:34:18.737+0530] {taskinstance.py:1157} INFO - Dependencies all met for dep_context=requeueable deps ti=<TaskInstance: hooks_demo.transfer manual__2023-11-03T07:59:14.612650+00:00 [queued]>
[2023-11-03T13:34:18.737+0530] {taskinstance.py:1359} INFO - Starting attempt 2 of 2
[2023-11-03T13:34:18.745+0530] {taskinstance.py:1380} INFO - Executing <Task(PythonOperator): transfer> on 2023-11-03 07:59:14.612650+00:00
[2023-11-03T13:34:18.749+0530] {standard_task_runner.py:57} INFO - Started process 1307154 to run task
[2023-11-03T13:34:18.750+0530] {standard_task_runner.py:84} INFO - Running: ['airflow', 'tasks', 'run', 'hooks_demo', 'transfer', 'manual__2023-11-03T07:59:14.612650+00:00', '--job-id', '4183', '--raw', '--subdir', 'DAGS_FOLDER/hooks.py', '--cfg-path', '/tmp/tmp9hdw7jo6']
[2023-11-03T13:34:18.751+0530] {standard_task_runner.py:85} INFO - Job 4183: Subtask transfer
[2023-11-03T13:34:18.772+0530] {task_command.py:415} INFO - Running <TaskInstance: hooks_demo.transfer manual__2023-11-03T07:59:14.612650+00:00 [running]> on host harika-Latitude-5511
[2023-11-03T13:34:18.887+0530] {taskinstance.py:1660} INFO - Exporting env vars: AIRFLOW_CTX_DAG_OWNER='Airflow' AIRFLOW_CTX_DAG_ID='hooks_demo' AIRFLOW_CTX_TASK_ID='transfer' AIRFLOW_CTX_EXECUTION_DATE='2023-11-03T07:59:14.612650+00:00' AIRFLOW_CTX_TRY_NUMBER='2' AIRFLOW_CTX_DAG_RUN_ID='manual__2023-11-03T07:59:14.612650+00:00'
[2023-11-03T13:34:18.893+0530] {taskinstance.py:1935} ERROR - Task failed with exception
Traceback (most recent call last):
  File "/home/harika/.local/lib/python3.10/site-packages/airflow/operators/python.py", line 192, in execute
    return_value = self.execute_callable()
  File "/home/harika/.local/lib/python3.10/site-packages/airflow/operators/python.py", line 209, in execute_callable
    return self.python_callable(*self.op_args, **self.op_kwargs)
  File "/home/harika/airflow/dags/hooks.py", line 20, in transfer_function
    source_conn = source_hook.get_conn()
  File "/home/harika/.local/lib/python3.10/site-packages/airflow/providers/postgres/hooks/postgres.py", line 125, in get_conn
    conn = deepcopy(self.connection or self.get_connection(conn_id))
  File "/home/harika/.local/lib/python3.10/site-packages/airflow/hooks/base.py", line 72, in get_connection
    conn = Connection.get_connection_from_secrets(conn_id)
  File "/home/harika/.local/lib/python3.10/site-packages/airflow/models/connection.py", line 477, in get_connection_from_secrets
    raise AirflowNotFoundException(f"The conn_id `{conn_id}` isn't defined")
airflow.exceptions.AirflowNotFoundException: The conn_id `postgres_conn` isn't defined
[2023-11-03T13:34:18.895+0530] {taskinstance.py:1398} INFO - Marking task as FAILED. dag_id=hooks_demo, task_id=transfer, execution_date=20231103T075914, start_date=20231103T080418, end_date=20231103T080418
[2023-11-03T13:34:18.909+0530] {standard_task_runner.py:104} ERROR - Failed to execute job 4183 for task transfer (The conn_id `postgres_conn` isn't defined; 1307154)
[2023-11-03T13:34:18.922+0530] {local_task_job_runner.py:228} INFO - Task exited with return code 1
[2023-11-03T13:34:18.933+0530] {taskinstance.py:2776} INFO - 0 downstream tasks scheduled from follow-on schedule check
