[2023-11-03T17:52:38.281+0530] {taskinstance.py:1157} INFO - Dependencies all met for dep_context=non-requeueable deps ti=<TaskInstance: hooks_demo.transfer manual__2023-11-03T12:17:33.780718+00:00 [queued]>
[2023-11-03T17:52:38.285+0530] {taskinstance.py:1157} INFO - Dependencies all met for dep_context=requeueable deps ti=<TaskInstance: hooks_demo.transfer manual__2023-11-03T12:17:33.780718+00:00 [queued]>
[2023-11-03T17:52:38.285+0530] {taskinstance.py:1359} INFO - Starting attempt 2 of 2
[2023-11-03T17:52:38.295+0530] {taskinstance.py:1380} INFO - Executing <Task(PythonOperator): transfer> on 2023-11-03 12:17:33.780718+00:00
[2023-11-03T17:52:38.298+0530] {standard_task_runner.py:57} INFO - Started process 11188 to run task
[2023-11-03T17:52:38.300+0530] {standard_task_runner.py:84} INFO - Running: ['airflow', 'tasks', 'run', 'hooks_demo', 'transfer', 'manual__2023-11-03T12:17:33.780718+00:00', '--job-id', '4243', '--raw', '--subdir', 'DAGS_FOLDER/hooks.py', '--cfg-path', '/tmp/tmp1a2rd1hh']
[2023-11-03T17:52:38.300+0530] {standard_task_runner.py:85} INFO - Job 4243: Subtask transfer
[2023-11-03T17:52:38.323+0530] {task_command.py:415} INFO - Running <TaskInstance: hooks_demo.transfer manual__2023-11-03T12:17:33.780718+00:00 [running]> on host harika-Latitude-5511
[2023-11-03T17:52:38.447+0530] {taskinstance.py:1660} INFO - Exporting env vars: AIRFLOW_CTX_DAG_OWNER='Airflow' AIRFLOW_CTX_DAG_ID='hooks_demo' AIRFLOW_CTX_TASK_ID='transfer' AIRFLOW_CTX_EXECUTION_DATE='2023-11-03T12:17:33.780718+00:00' AIRFLOW_CTX_TRY_NUMBER='2' AIRFLOW_CTX_DAG_RUN_ID='manual__2023-11-03T12:17:33.780718+00:00'
[2023-11-03T17:52:38.451+0530] {base.py:73} INFO - Using connection ID 'postgres_conn' for task execution.
[2023-11-03T17:52:38.463+0530] {taskinstance.py:1935} ERROR - Task failed with exception
Traceback (most recent call last):
  File "/home/harika/.local/lib/python3.10/site-packages/airflow/operators/python.py", line 192, in execute
    return_value = self.execute_callable()
  File "/home/harika/.local/lib/python3.10/site-packages/airflow/operators/python.py", line 209, in execute_callable
    return self.python_callable(*self.op_args, **self.op_kwargs)
  File "/home/harika/airflow/dags/hooks.py", line 20, in transfer_function
    source_conn = source_hook.get_conn()
  File "/home/harika/.local/lib/python3.10/site-packages/airflow/providers/postgres/hooks/postgres.py", line 155, in get_conn
    self.conn = psycopg2.connect(**conn_args)
  File "/home/harika/.local/lib/python3.10/site-packages/psycopg2/__init__.py", line 122, in connect
    conn = _connect(dsn, connection_factory=connection_factory, **kwasync)
psycopg2.OperationalError: connection to server at "localhost" (127.0.0.1), port 5432 failed: FATAL:  database "airflow" does not exist

[2023-11-03T17:52:38.466+0530] {taskinstance.py:1398} INFO - Marking task as FAILED. dag_id=hooks_demo, task_id=transfer, execution_date=20231103T121733, start_date=20231103T122238, end_date=20231103T122238
[2023-11-03T17:52:38.479+0530] {standard_task_runner.py:104} ERROR - Failed to execute job 4243 for task transfer (connection to server at "localhost" (127.0.0.1), port 5432 failed: FATAL:  database "airflow" does not exist
; 11188)
[2023-11-03T17:52:38.512+0530] {local_task_job_runner.py:228} INFO - Task exited with return code 1
[2023-11-03T17:52:38.538+0530] {taskinstance.py:2776} INFO - 0 downstream tasks scheduled from follow-on schedule check
