[2023-11-06T11:08:04.567+0530] {taskinstance.py:1157} INFO - Dependencies all met for dep_context=non-requeueable deps ti=<TaskInstance: hooks_demo.transfer manual__2023-11-06T05:32:59.222317+00:00 [queued]>
[2023-11-06T11:08:04.571+0530] {taskinstance.py:1157} INFO - Dependencies all met for dep_context=requeueable deps ti=<TaskInstance: hooks_demo.transfer manual__2023-11-06T05:32:59.222317+00:00 [queued]>
[2023-11-06T11:08:04.571+0530] {taskinstance.py:1359} INFO - Starting attempt 2 of 2
[2023-11-06T11:08:04.582+0530] {taskinstance.py:1380} INFO - Executing <Task(PythonOperator): transfer> on 2023-11-06 05:32:59.222317+00:00
[2023-11-06T11:08:04.585+0530] {standard_task_runner.py:57} INFO - Started process 13769 to run task
[2023-11-06T11:08:04.587+0530] {standard_task_runner.py:84} INFO - Running: ['airflow', 'tasks', 'run', 'hooks_demo', 'transfer', 'manual__2023-11-06T05:32:59.222317+00:00', '--job-id', '4289', '--raw', '--subdir', 'DAGS_FOLDER/hooks.py', '--cfg-path', '/tmp/tmpvra7phvu']
[2023-11-06T11:08:04.588+0530] {standard_task_runner.py:85} INFO - Job 4289: Subtask transfer
[2023-11-06T11:08:04.613+0530] {task_command.py:415} INFO - Running <TaskInstance: hooks_demo.transfer manual__2023-11-06T05:32:59.222317+00:00 [running]> on host harika-Latitude-5511
[2023-11-06T11:08:04.739+0530] {taskinstance.py:1660} INFO - Exporting env vars: AIRFLOW_CTX_DAG_OWNER='Airflow' AIRFLOW_CTX_DAG_ID='hooks_demo' AIRFLOW_CTX_TASK_ID='transfer' AIRFLOW_CTX_EXECUTION_DATE='2023-11-06T05:32:59.222317+00:00' AIRFLOW_CTX_TRY_NUMBER='2' AIRFLOW_CTX_DAG_RUN_ID='manual__2023-11-06T05:32:59.222317+00:00'
[2023-11-06T11:08:04.744+0530] {base.py:73} INFO - Using connection ID 'postgres_conn' for task execution.
[2023-11-06T11:08:04.758+0530] {base.py:73} INFO - Using connection ID 'postgres_conn' for task execution.
[2023-11-06T11:08:04.767+0530] {logging_mixin.py:151} INFO - #############################
[2023-11-06T11:08:04.767+0530] {logging_mixin.py:151} INFO - \dt
[2023-11-06T11:08:04.768+0530] {taskinstance.py:1935} ERROR - Task failed with exception
Traceback (most recent call last):
  File "/home/harika/.local/lib/python3.10/site-packages/airflow/operators/python.py", line 192, in execute
    return_value = self.execute_callable()
  File "/home/harika/.local/lib/python3.10/site-packages/airflow/operators/python.py", line 209, in execute_callable
    return self.python_callable(*self.op_args, **self.op_kwargs)
  File "/home/harika/airflow/dags/hooks.py", line 31, in transfer_function
    source_cursor.execute(query)
psycopg2.errors.UndefinedTable: relation "source_city_table" does not exist
LINE 1: select * from source_city_table;
                      ^

[2023-11-06T11:08:04.771+0530] {taskinstance.py:1398} INFO - Marking task as FAILED. dag_id=hooks_demo, task_id=transfer, execution_date=20231106T053259, start_date=20231106T053804, end_date=20231106T053804
[2023-11-06T11:08:04.785+0530] {standard_task_runner.py:104} ERROR - Failed to execute job 4289 for task transfer (relation "source_city_table" does not exist
LINE 1: select * from source_city_table;
                      ^
; 13769)
[2023-11-06T11:08:04.799+0530] {local_task_job_runner.py:228} INFO - Task exited with return code 1
[2023-11-06T11:08:04.811+0530] {taskinstance.py:2776} INFO - 0 downstream tasks scheduled from follow-on schedule check
